2024-01-29 18:21:10,610 ERROR: Exception on / [GET] [in D:\Coding\Python\flask\micoblog05\.venv\Lib\site-packages\flask\app.py:828]
Traceback (most recent call last):
  File "D:\Coding\Python\flask\micoblog05\.venv\Lib\site-packages\sqlalchemy\engine\base.py", line 1969, in _exec_single_context
    self.dialect.do_execute(
  File "D:\Coding\Python\flask\micoblog05\.venv\Lib\site-packages\sqlalchemy\engine\default.py", line 922, in do_execute
    cursor.execute(statement, parameters)
sqlite3.OperationalError: no such table: user

The above exception was the direct cause of the following exception:

Traceback (most recent call last):
  File "D:\Coding\Python\flask\micoblog05\.venv\Lib\site-packages\flask\app.py", line 1463, in wsgi_app
    response = self.full_dispatch_request()
               ^^^^^^^^^^^^^^^^^^^^^^^^^^^^
  File "D:\Coding\Python\flask\micoblog05\.venv\Lib\site-packages\flask\app.py", line 872, in full_dispatch_request
    rv = self.handle_user_exception(e)
         ^^^^^^^^^^^^^^^^^^^^^^^^^^^^^
  File "D:\Coding\Python\flask\micoblog05\.venv\Lib\site-packages\flask\app.py", line 868, in full_dispatch_request
    rv = self.preprocess_request()
         ^^^^^^^^^^^^^^^^^^^^^^^^^
  File "D:\Coding\Python\flask\micoblog05\.venv\Lib\site-packages\flask\app.py", line 1243, in preprocess_request
    rv = self.ensure_sync(before_func)()
         ^^^^^^^^^^^^^^^^^^^^^^^^^^^^^^^
  File "D:\Coding\Python\flask\micoblog05\app\routes.py", line 79, in before_request
    if current_user.is_authenticated:
       ^^^^^^^^^^^^^^^^^^^^^^^^^^^^^
  File "D:\Coding\Python\flask\micoblog05\.venv\Lib\site-packages\werkzeug\local.py", line 311, in __get__
    obj = instance._get_current_object()
          ^^^^^^^^^^^^^^^^^^^^^^^^^^^^^^
  File "D:\Coding\Python\flask\micoblog05\.venv\Lib\site-packages\werkzeug\local.py", line 515, in _get_current_object
    return get_name(local())
                    ^^^^^^^
  File "D:\Coding\Python\flask\micoblog05\.venv\Lib\site-packages\flask_login\utils.py", line 25, in <lambda>
    current_user = LocalProxy(lambda: _get_user())
                                      ^^^^^^^^^^^
  File "D:\Coding\Python\flask\micoblog05\.venv\Lib\site-packages\flask_login\utils.py", line 370, in _get_user
    current_app.login_manager._load_user()
  File "D:\Coding\Python\flask\micoblog05\.venv\Lib\site-packages\flask_login\login_manager.py", line 364, in _load_user
    user = self._user_callback(user_id)
           ^^^^^^^^^^^^^^^^^^^^^^^^^^^^
  File "D:\Coding\Python\flask\micoblog05\app\models.py", line 16, in load_user
    return User.query.get(int(id))
           ^^^^^^^^^^^^^^^^^^^^^^^
  File "<string>", line 2, in get
  File "D:\Coding\Python\flask\micoblog05\.venv\Lib\site-packages\sqlalchemy\util\deprecations.py", line 386, in warned
    return fn(*args, **kwargs)  # type: ignore[no-any-return]
           ^^^^^^^^^^^^^^^^^^^
  File "D:\Coding\Python\flask\micoblog05\.venv\Lib\site-packages\sqlalchemy\orm\query.py", line 1136, in get
    return self._get_impl(ident, loading.load_on_pk_identity)
           ^^^^^^^^^^^^^^^^^^^^^^^^^^^^^^^^^^^^^^^^^^^^^^^^^^
  File "D:\Coding\Python\flask\micoblog05\.venv\Lib\site-packages\sqlalchemy\orm\query.py", line 1145, in _get_impl
    return self.session._get_impl(
           ^^^^^^^^^^^^^^^^^^^^^^^
  File "D:\Coding\Python\flask\micoblog05\.venv\Lib\site-packages\sqlalchemy\orm\session.py", line 3833, in _get_impl
    return db_load_fn(
           ^^^^^^^^^^^
  File "D:\Coding\Python\flask\micoblog05\.venv\Lib\site-packages\sqlalchemy\orm\loading.py", line 692, in load_on_pk_identity
    session.execute(
  File "D:\Coding\Python\flask\micoblog05\.venv\Lib\site-packages\sqlalchemy\orm\session.py", line 2308, in execute
    return self._execute_internal(
           ^^^^^^^^^^^^^^^^^^^^^^^
  File "D:\Coding\Python\flask\micoblog05\.venv\Lib\site-packages\sqlalchemy\orm\session.py", line 2190, in _execute_internal
    result: Result[Any] = compile_state_cls.orm_execute_statement(
                          ^^^^^^^^^^^^^^^^^^^^^^^^^^^^^^^^^^^^^^^^
  File "D:\Coding\Python\flask\micoblog05\.venv\Lib\site-packages\sqlalchemy\orm\context.py", line 293, in orm_execute_statement
    result = conn.execute(
             ^^^^^^^^^^^^^
  File "D:\Coding\Python\flask\micoblog05\.venv\Lib\site-packages\sqlalchemy\engine\base.py", line 1416, in execute
    return meth(
           ^^^^^
  File "D:\Coding\Python\flask\micoblog05\.venv\Lib\site-packages\sqlalchemy\sql\elements.py", line 517, in _execute_on_connection
    return connection._execute_clauseelement(
           ^^^^^^^^^^^^^^^^^^^^^^^^^^^^^^^^^^
  File "D:\Coding\Python\flask\micoblog05\.venv\Lib\site-packages\sqlalchemy\engine\base.py", line 1639, in _execute_clauseelement
    ret = self._execute_context(
          ^^^^^^^^^^^^^^^^^^^^^^
  File "D:\Coding\Python\flask\micoblog05\.venv\Lib\site-packages\sqlalchemy\engine\base.py", line 1848, in _execute_context
    return self._exec_single_context(
           ^^^^^^^^^^^^^^^^^^^^^^^^^^
  File "D:\Coding\Python\flask\micoblog05\.venv\Lib\site-packages\sqlalchemy\engine\base.py", line 1988, in _exec_single_context
    self._handle_dbapi_exception(
  File "D:\Coding\Python\flask\micoblog05\.venv\Lib\site-packages\sqlalchemy\engine\base.py", line 2344, in _handle_dbapi_exception
    raise sqlalchemy_exception.with_traceback(exc_info[2]) from e
  File "D:\Coding\Python\flask\micoblog05\.venv\Lib\site-packages\sqlalchemy\engine\base.py", line 1969, in _exec_single_context
    self.dialect.do_execute(
  File "D:\Coding\Python\flask\micoblog05\.venv\Lib\site-packages\sqlalchemy\engine\default.py", line 922, in do_execute
    cursor.execute(statement, parameters)
sqlalchemy.exc.OperationalError: (sqlite3.OperationalError) no such table: user
[SQL: SELECT user.id AS user_id, user.username AS user_username, user.email AS user_email, user.password_hash AS user_password_hash, user.about_me AS user_about_me, user.last_seen AS user_last_seen 
FROM user 
WHERE user.id = ?]
[parameters: (2,)]
(Background on this error at: https://sqlalche.me/e/20/e3q8)
2024-01-29 18:24:05,362 INFO: micoblog05 startup [in D:\Coding\Python\flask\micoblog05\app\__init__.py:46]
2024-01-29 18:24:17,341 INFO: micoblog05 startup [in D:\Coding\Python\flask\micoblog05\app\__init__.py:46]
2024-01-29 18:25:58,359 INFO: micoblog05 startup [in D:\Coding\Python\flask\micoblog05\app\__init__.py:46]
2024-01-29 18:26:02,821 INFO: micoblog05 startup [in D:\Coding\Python\flask\micoblog05\app\__init__.py:46]
2024-01-29 18:26:19,223 INFO: micoblog05 startup [in D:\Coding\Python\flask\micoblog05\app\__init__.py:46]
2024-01-29 18:26:56,587 INFO: micoblog05 startup [in D:\Coding\Python\flask\micoblog05\app\__init__.py:46]
2024-01-30 10:05:45,065 INFO: micoblog05 startup [in D:\Coding\Python\flask\micoblog05\app\__init__.py:46]
2024-01-30 10:13:16,320 INFO: micoblog05 startup [in D:\Coding\Python\flask\micoblog05\app\__init__.py:46]
2024-01-30 10:13:24,330 INFO: micoblog05 startup [in D:\Coding\Python\flask\micoblog05\app\__init__.py:46]
2024-01-30 10:17:00,008 INFO: micoblog05 startup [in D:\Coding\Python\flask\micoblog05\app\__init__.py:46]
2024-01-30 10:20:37,511 INFO: micoblog05 startup [in D:\Coding\Python\flask\micoblog05\app\__init__.py:46]
2024-01-30 10:35:53,783 INFO: micoblog05 startup [in D:\Coding\Python\flask\micoblog05\app\__init__.py:46]
2024-01-30 10:36:13,724 INFO: micoblog05 startup [in D:\Coding\Python\flask\micoblog05\app\__init__.py:46]
