2024-01-30 10:44:10,946 ERROR: Exception on / [GET] [in D:\Coding\Python\flask\micoblog05\.venv\Lib\site-packages\flask\app.py:828]
Traceback (most recent call last):
  File "D:\Coding\Python\flask\micoblog05\.venv\Lib\site-packages\sqlalchemy\engine\base.py", line 1969, in _exec_single_context
    self.dialect.do_execute(
  File "D:\Coding\Python\flask\micoblog05\.venv\Lib\site-packages\sqlalchemy\engine\default.py", line 922, in do_execute
    cursor.execute(statement, parameters)
sqlite3.OperationalError: no such table: user

The above exception was the direct cause of the following exception:

Traceback (most recent call last):
  File "D:\Coding\Python\flask\micoblog05\.venv\Lib\site-packages\flask\app.py", line 1463, in wsgi_app
    response = self.full_dispatch_request()
               ^^^^^^^^^^^^^^^^^^^^^^^^^^^^
  File "D:\Coding\Python\flask\micoblog05\.venv\Lib\site-packages\flask\app.py", line 872, in full_dispatch_request
    rv = self.handle_user_exception(e)
         ^^^^^^^^^^^^^^^^^^^^^^^^^^^^^
  File "D:\Coding\Python\flask\micoblog05\.venv\Lib\site-packages\flask\app.py", line 868, in full_dispatch_request
    rv = self.preprocess_request()
         ^^^^^^^^^^^^^^^^^^^^^^^^^
  File "D:\Coding\Python\flask\micoblog05\.venv\Lib\site-packages\flask\app.py", line 1243, in preprocess_request
    rv = self.ensure_sync(before_func)()
         ^^^^^^^^^^^^^^^^^^^^^^^^^^^^^^^
  File "D:\Coding\Python\flask\micoblog05\app\routes.py", line 89, in before_request
    if current_user.is_authenticated:
       ^^^^^^^^^^^^^^^^^^^^^^^^^^^^^
  File "D:\Coding\Python\flask\micoblog05\.venv\Lib\site-packages\werkzeug\local.py", line 311, in __get__
    obj = instance._get_current_object()
          ^^^^^^^^^^^^^^^^^^^^^^^^^^^^^^
  File "D:\Coding\Python\flask\micoblog05\.venv\Lib\site-packages\werkzeug\local.py", line 515, in _get_current_object
    return get_name(local())
                    ^^^^^^^
  File "D:\Coding\Python\flask\micoblog05\.venv\Lib\site-packages\flask_login\utils.py", line 25, in <lambda>
    current_user = LocalProxy(lambda: _get_user())
                                      ^^^^^^^^^^^
  File "D:\Coding\Python\flask\micoblog05\.venv\Lib\site-packages\flask_login\utils.py", line 370, in _get_user
    current_app.login_manager._load_user()
  File "D:\Coding\Python\flask\micoblog05\.venv\Lib\site-packages\flask_login\login_manager.py", line 364, in _load_user
    user = self._user_callback(user_id)
           ^^^^^^^^^^^^^^^^^^^^^^^^^^^^
  File "D:\Coding\Python\flask\micoblog05\app\models.py", line 16, in load_user
    return User.query.get(int(id))
           ^^^^^^^^^^^^^^^^^^^^^^^
  File "<string>", line 2, in get
  File "D:\Coding\Python\flask\micoblog05\.venv\Lib\site-packages\sqlalchemy\util\deprecations.py", line 386, in warned
    return fn(*args, **kwargs)  # type: ignore[no-any-return]
           ^^^^^^^^^^^^^^^^^^^
  File "D:\Coding\Python\flask\micoblog05\.venv\Lib\site-packages\sqlalchemy\orm\query.py", line 1136, in get
    return self._get_impl(ident, loading.load_on_pk_identity)
           ^^^^^^^^^^^^^^^^^^^^^^^^^^^^^^^^^^^^^^^^^^^^^^^^^^
  File "D:\Coding\Python\flask\micoblog05\.venv\Lib\site-packages\sqlalchemy\orm\query.py", line 1145, in _get_impl
    return self.session._get_impl(
           ^^^^^^^^^^^^^^^^^^^^^^^
  File "D:\Coding\Python\flask\micoblog05\.venv\Lib\site-packages\sqlalchemy\orm\session.py", line 3833, in _get_impl
    return db_load_fn(
           ^^^^^^^^^^^
  File "D:\Coding\Python\flask\micoblog05\.venv\Lib\site-packages\sqlalchemy\orm\loading.py", line 692, in load_on_pk_identity
    session.execute(
  File "D:\Coding\Python\flask\micoblog05\.venv\Lib\site-packages\sqlalchemy\orm\session.py", line 2308, in execute
    return self._execute_internal(
           ^^^^^^^^^^^^^^^^^^^^^^^
  File "D:\Coding\Python\flask\micoblog05\.venv\Lib\site-packages\sqlalchemy\orm\session.py", line 2190, in _execute_internal
    result: Result[Any] = compile_state_cls.orm_execute_statement(
                          ^^^^^^^^^^^^^^^^^^^^^^^^^^^^^^^^^^^^^^^^
  File "D:\Coding\Python\flask\micoblog05\.venv\Lib\site-packages\sqlalchemy\orm\context.py", line 293, in orm_execute_statement
    result = conn.execute(
             ^^^^^^^^^^^^^
  File "D:\Coding\Python\flask\micoblog05\.venv\Lib\site-packages\sqlalchemy\engine\base.py", line 1416, in execute
    return meth(
           ^^^^^
  File "D:\Coding\Python\flask\micoblog05\.venv\Lib\site-packages\sqlalchemy\sql\elements.py", line 517, in _execute_on_connection
    return connection._execute_clauseelement(
           ^^^^^^^^^^^^^^^^^^^^^^^^^^^^^^^^^^
  File "D:\Coding\Python\flask\micoblog05\.venv\Lib\site-packages\sqlalchemy\engine\base.py", line 1639, in _execute_clauseelement
    ret = self._execute_context(
          ^^^^^^^^^^^^^^^^^^^^^^
  File "D:\Coding\Python\flask\micoblog05\.venv\Lib\site-packages\sqlalchemy\engine\base.py", line 1848, in _execute_context
    return self._exec_single_context(
           ^^^^^^^^^^^^^^^^^^^^^^^^^^
  File "D:\Coding\Python\flask\micoblog05\.venv\Lib\site-packages\sqlalchemy\engine\base.py", line 1988, in _exec_single_context
    self._handle_dbapi_exception(
  File "D:\Coding\Python\flask\micoblog05\.venv\Lib\site-packages\sqlalchemy\engine\base.py", line 2344, in _handle_dbapi_exception
    raise sqlalchemy_exception.with_traceback(exc_info[2]) from e
  File "D:\Coding\Python\flask\micoblog05\.venv\Lib\site-packages\sqlalchemy\engine\base.py", line 1969, in _exec_single_context
    self.dialect.do_execute(
  File "D:\Coding\Python\flask\micoblog05\.venv\Lib\site-packages\sqlalchemy\engine\default.py", line 922, in do_execute
    cursor.execute(statement, parameters)
sqlalchemy.exc.OperationalError: (sqlite3.OperationalError) no such table: user
[SQL: SELECT user.id AS user_id, user.username AS user_username, user.email AS user_email, user.password_hash AS user_password_hash, user.about_me AS user_about_me, user.last_seen AS user_last_seen 
FROM user 
WHERE user.id = ?]
[parameters: (1,)]
(Background on this error at: https://sqlalche.me/e/20/e3q8)
2024-01-30 10:48:58,072 INFO: micoblog05 startup [in D:\Coding\Python\flask\micoblog05\app\__init__.py:46]
2024-01-30 10:49:12,922 INFO: micoblog05 startup [in D:\Coding\Python\flask\micoblog05\app\__init__.py:46]
2024-01-30 10:49:18,831 INFO: micoblog05 startup [in D:\Coding\Python\flask\micoblog05\app\__init__.py:46]
2024-01-30 10:49:43,903 ERROR: Exception on /user/fei [GET] [in D:\Coding\Python\flask\micoblog05\.venv\Lib\site-packages\flask\app.py:828]
Traceback (most recent call last):
  File "D:\Coding\Python\flask\micoblog05\.venv\Lib\site-packages\flask\app.py", line 1463, in wsgi_app
    response = self.full_dispatch_request()
               ^^^^^^^^^^^^^^^^^^^^^^^^^^^^
  File "D:\Coding\Python\flask\micoblog05\.venv\Lib\site-packages\flask\app.py", line 872, in full_dispatch_request
    rv = self.handle_user_exception(e)
         ^^^^^^^^^^^^^^^^^^^^^^^^^^^^^
  File "D:\Coding\Python\flask\micoblog05\.venv\Lib\site-packages\flask\app.py", line 870, in full_dispatch_request
    rv = self.dispatch_request()
         ^^^^^^^^^^^^^^^^^^^^^^^
  File "D:\Coding\Python\flask\micoblog05\.venv\Lib\site-packages\flask\app.py", line 855, in dispatch_request
    return self.ensure_sync(self.view_functions[rule.endpoint])(**view_args)  # type: ignore[no-any-return]
           ^^^^^^^^^^^^^^^^^^^^^^^^^^^^^^^^^^^^^^^^^^^^^^^^^^^^^^^^^^^^^^^^^
  File "D:\Coding\Python\flask\micoblog05\.venv\Lib\site-packages\flask_login\utils.py", line 290, in decorated_view
    return current_app.ensure_sync(func)(*args, **kwargs)
           ^^^^^^^^^^^^^^^^^^^^^^^^^^^^^^^^^^^^^^^^^^^^^^
  File "D:\Coding\Python\flask\micoblog05\app\routes.py", line 85, in user
    return render_template('user.html',user=user,posts=posts)
           ^^^^^^^^^^^^^^^^^^^^^^^^^^^^^^^^^^^^^^^^^^^^^^^^^^
  File "D:\Coding\Python\flask\micoblog05\.venv\Lib\site-packages\flask\templating.py", line 150, in render_template
    return _render(app, template, context)
           ^^^^^^^^^^^^^^^^^^^^^^^^^^^^^^^
  File "D:\Coding\Python\flask\micoblog05\.venv\Lib\site-packages\flask\templating.py", line 131, in _render
    rv = template.render(context)
         ^^^^^^^^^^^^^^^^^^^^^^^^
  File "D:\Coding\Python\flask\micoblog05\.venv\Lib\site-packages\jinja2\environment.py", line 1301, in render
    self.environment.handle_exception()
  File "D:\Coding\Python\flask\micoblog05\.venv\Lib\site-packages\jinja2\environment.py", line 936, in handle_exception
    raise rewrite_traceback_stack(source=source)
  File "D:\Coding\Python\flask\micoblog05\app\templates\user.html", line 1, in top-level template code
    {% extends "base.html" %}
  File "D:\Coding\Python\flask\micoblog05\app\templates\base.html", line 35, in top-level template code
    {% block content %}{% endblock %}
    ^^^^^^^^^^^^^^^^^^^^^^^^^
  File "D:\Coding\Python\flask\micoblog05\app\templates\user.html", line 16, in block 'content'
    {% include '_post.html' %}
    ^^^^^^^^^^^^^^^^^^^^^^^^^
  File "D:\Coding\Python\flask\micoblog05\app\templates\_post.html", line 5, in top-level template code
    <a href="{{ url.for('user',username=post.author.username) }}">
    ^^^^^^^^^^^^^^^^^^^^^^^^^
  File "D:\Coding\Python\flask\micoblog05\.venv\Lib\site-packages\jinja2\environment.py", line 485, in getattr
    return getattr(obj, attribute)
           ^^^^^^^^^^^^^^^^^^^^^^^
jinja2.exceptions.UndefinedError: 'url' is undefined
